[rospy.client][INFO] 2018-12-19 11:05:41,357: init_node, name[/nao_behaviors], pid[6328]
[xmlrpc][INFO] 2018-12-19 11:05:41,357: XML-RPC server binding to 0.0.0.0:0
[xmlrpc][INFO] 2018-12-19 11:05:41,357: Started XML-RPC server [http://NAOrobUSB001:35599/]
[rospy.init][INFO] 2018-12-19 11:05:41,357: ROS Slave URI: [http://NAOrobUSB001:35599/]
[rospy.impl.masterslave][INFO] 2018-12-19 11:05:41,357: _ready: http://NAOrobUSB001:35599/
[rospy.registration][INFO] 2018-12-19 11:05:41,358: Registering with master node http://localhost:11311
[xmlrpc][INFO] 2018-12-19 11:05:41,358: xml rpc node: starting XML-RPC server
[rospy.init][INFO] 2018-12-19 11:05:41,458: registered with master
[rospy.rosout][INFO] 2018-12-19 11:05:41,458: initializing /rosout core topic
[rospy.rosout][INFO] 2018-12-19 11:05:41,460: connected to core topic /rosout
[rospy.simtime][INFO] 2018-12-19 11:05:41,461: /use_sim_time is not set, will not subscribe to simulated time [/clock] topic
[rosout][INFO] 2018-12-19 11:05:41,480: nao_behaviors running...
[rospy.internal][INFO] 2018-12-19 11:05:41,666: topic[/rosout] adding connection to [/rosout], count 0
[rospy.internal][INFO] 2018-12-19 11:15:00,839: topic[/run_behavior/cancel] adding connection to [http://NAOrobUSB001:35929/], count 0
[rospy.internal][INFO] 2018-12-19 11:15:00,840: topic[/run_behavior/goal] adding connection to [http://NAOrobUSB001:35929/], count 0
[rospy.internal][INFO] 2018-12-19 11:15:01,025: topic[/run_behavior/status] adding connection to [/nao_behav_ac], count 0
[rospy.internal][INFO] 2018-12-19 11:15:01,027: topic[/run_behavior/feedback] adding connection to [/nao_behav_ac], count 0
[rospy.internal][INFO] 2018-12-19 11:15:01,028: topic[/run_behavior/result] adding connection to [/nao_behav_ac], count 0
[rospy.internal][ERROR] 2018-12-19 11:15:23,085: Unable to initiate TCP/IP socket to NAOrobUSB001:47937 (http://NAOrobUSB001:35929/): Traceback (most recent call last):
  File "/opt/ros/kinetic/lib/python2.7/dist-packages/rospy/impl/tcpros_base.py", line 557, in connect
    self.read_header()
  File "/opt/ros/kinetic/lib/python2.7/dist-packages/rospy/impl/tcpros_base.py", line 650, in read_header
    self._validate_header(read_ros_handshake_header(sock, self.read_buff, self.protocol.buff_size))
  File "/opt/ros/kinetic/lib/python2.7/dist-packages/rospy/impl/tcpros_base.py", line 593, in _validate_header
    raise TransportInitError("remote error reported: %s"%header['error'])
TransportInitError: remote error reported: received a connection for a nonexistent topic [/run_behavior/cancel] from [TCPROS connection on port 47937 to [127.0.0.1:56728 on socket 10]] [/nao_behaviors].

[rospy.internal][ERROR] 2018-12-19 11:15:23,085: Unable to initiate TCP/IP socket to NAOrobUSB001:47937 (http://NAOrobUSB001:35929/): Traceback (most recent call last):
  File "/opt/ros/kinetic/lib/python2.7/dist-packages/rospy/impl/tcpros_base.py", line 557, in connect
    self.read_header()
  File "/opt/ros/kinetic/lib/python2.7/dist-packages/rospy/impl/tcpros_base.py", line 650, in read_header
    self._validate_header(read_ros_handshake_header(sock, self.read_buff, self.protocol.buff_size))
  File "/opt/ros/kinetic/lib/python2.7/dist-packages/rospy/impl/tcpros_base.py", line 593, in _validate_header
    raise TransportInitError("remote error reported: %s"%header['error'])
TransportInitError: remote error reported: received a connection for a nonexistent topic [/run_behavior/goal] from [TCPROS connection on port 47937 to [127.0.0.1:56732 on socket 10]] [/nao_behaviors].

[rospy.internal][INFO] 2018-12-19 11:15:23,348: topic[/run_behavior/status] removing connection to /nao_behav_ac
[rospy.internal][INFO] 2018-12-19 11:15:23,348: topic[/run_behavior/result] removing connection to /nao_behav_ac
[rospy.internal][INFO] 2018-12-19 11:15:23,348: topic[/run_behavior/feedback] removing connection to /nao_behav_ac
[rospy.internal][WARNING] 2018-12-19 11:15:24,087: Unknown error initiating TCP/IP socket to NAOrobUSB001:47937 (http://NAOrobUSB001:35929/): Traceback (most recent call last):
  File "/opt/ros/kinetic/lib/python2.7/dist-packages/rospy/impl/tcpros_base.py", line 555, in connect
    self.socket.connect((dest_addr, dest_port))
  File "/usr/lib/python2.7/socket.py", line 228, in meth
    return getattr(self._sock,name)(*args)
error: [Errno 111] Connection refused

[rospy.internal][WARNING] 2018-12-19 11:15:24,087: Unknown error initiating TCP/IP socket to NAOrobUSB001:47937 (http://NAOrobUSB001:35929/): Traceback (most recent call last):
  File "/opt/ros/kinetic/lib/python2.7/dist-packages/rospy/impl/tcpros_base.py", line 555, in connect
    self.socket.connect((dest_addr, dest_port))
  File "/usr/lib/python2.7/socket.py", line 228, in meth
    return getattr(self._sock,name)(*args)
error: [Errno 111] Connection refused

[rospy.internal][INFO] 2018-12-19 11:15:24,087: topic[/run_behavior/cancel] removing connection to http://NAOrobUSB001:35929/
[rospy.internal][INFO] 2018-12-19 11:15:24,088: topic[/run_behavior/goal] removing connection to http://NAOrobUSB001:35929/
[rospy.internal][INFO] 2018-12-19 11:16:26,375: topic[/run_behavior/cancel] adding connection to [http://NAOrobUSB001:38869/], count 0
[rospy.internal][INFO] 2018-12-19 11:16:26,376: topic[/run_behavior/goal] adding connection to [http://NAOrobUSB001:38869/], count 0
[rospy.internal][INFO] 2018-12-19 11:16:26,562: topic[/run_behavior/status] adding connection to [/nao_behav_ac], count 0
[rospy.internal][INFO] 2018-12-19 11:16:26,563: topic[/run_behavior/feedback] adding connection to [/nao_behav_ac], count 0
[rospy.internal][INFO] 2018-12-19 11:16:26,564: topic[/run_behavior/result] adding connection to [/nao_behav_ac], count 0
[rospy.internal][ERROR] 2018-12-19 11:16:48,639: Unable to initiate TCP/IP socket to NAOrobUSB001:60597 (http://NAOrobUSB001:38869/): Traceback (most recent call last):
  File "/opt/ros/kinetic/lib/python2.7/dist-packages/rospy/impl/tcpros_base.py", line 557, in connect
    self.read_header()
  File "/opt/ros/kinetic/lib/python2.7/dist-packages/rospy/impl/tcpros_base.py", line 650, in read_header
    self._validate_header(read_ros_handshake_header(sock, self.read_buff, self.protocol.buff_size))
  File "/opt/ros/kinetic/lib/python2.7/dist-packages/rospy/impl/tcpros_base.py", line 593, in _validate_header
    raise TransportInitError("remote error reported: %s"%header['error'])
TransportInitError: remote error reported: received a connection for a nonexistent topic [/run_behavior/cancel] from [TCPROS connection on port 60597 to [127.0.0.1:51874 on socket 10]] [/nao_behaviors].

[rospy.internal][ERROR] 2018-12-19 11:16:48,640: Unable to initiate TCP/IP socket to NAOrobUSB001:60597 (http://NAOrobUSB001:38869/): Traceback (most recent call last):
  File "/opt/ros/kinetic/lib/python2.7/dist-packages/rospy/impl/tcpros_base.py", line 557, in connect
    self.read_header()
  File "/opt/ros/kinetic/lib/python2.7/dist-packages/rospy/impl/tcpros_base.py", line 650, in read_header
    self._validate_header(read_ros_handshake_header(sock, self.read_buff, self.protocol.buff_size))
  File "/opt/ros/kinetic/lib/python2.7/dist-packages/rospy/impl/tcpros_base.py", line 593, in _validate_header
    raise TransportInitError("remote error reported: %s"%header['error'])
TransportInitError: remote error reported: received a connection for a nonexistent topic [/run_behavior/goal] from [TCPROS connection on port 60597 to [127.0.0.1:51878 on socket 10]] [/nao_behaviors].

[rospy.internal][INFO] 2018-12-19 11:16:48,881: topic[/run_behavior/status] removing connection to /nao_behav_ac
[rospy.internal][INFO] 2018-12-19 11:16:48,883: topic[/run_behavior/result] removing connection to /nao_behav_ac
[rospy.internal][INFO] 2018-12-19 11:16:48,883: topic[/run_behavior/feedback] removing connection to /nao_behav_ac
[rospy.internal][WARNING] 2018-12-19 11:16:49,641: Unknown error initiating TCP/IP socket to NAOrobUSB001:60597 (http://NAOrobUSB001:38869/): Traceback (most recent call last):
  File "/opt/ros/kinetic/lib/python2.7/dist-packages/rospy/impl/tcpros_base.py", line 555, in connect
    self.socket.connect((dest_addr, dest_port))
  File "/usr/lib/python2.7/socket.py", line 228, in meth
    return getattr(self._sock,name)(*args)
error: [Errno 111] Connection refused

[rospy.internal][INFO] 2018-12-19 11:16:49,641: topic[/run_behavior/cancel] removing connection to http://NAOrobUSB001:38869/
[rospy.internal][WARNING] 2018-12-19 11:16:49,642: Unknown error initiating TCP/IP socket to NAOrobUSB001:60597 (http://NAOrobUSB001:38869/): Traceback (most recent call last):
  File "/opt/ros/kinetic/lib/python2.7/dist-packages/rospy/impl/tcpros_base.py", line 555, in connect
    self.socket.connect((dest_addr, dest_port))
  File "/usr/lib/python2.7/socket.py", line 228, in meth
    return getattr(self._sock,name)(*args)
error: [Errno 111] Connection refused

[rospy.internal][INFO] 2018-12-19 11:16:49,642: topic[/run_behavior/goal] removing connection to http://NAOrobUSB001:38869/
[rospy.internal][INFO] 2018-12-19 11:22:44,758: topic[/run_behavior/cancel] adding connection to [http://NAOrobUSB001:42315/], count 0
[rospy.internal][INFO] 2018-12-19 11:22:44,759: topic[/run_behavior/goal] adding connection to [http://NAOrobUSB001:42315/], count 0
[rospy.internal][INFO] 2018-12-19 11:22:44,916: topic[/run_behavior/status] adding connection to [/nao_behav_ac], count 0
[rospy.internal][INFO] 2018-12-19 11:22:44,916: topic[/run_behavior/feedback] adding connection to [/nao_behav_ac], count 0
[rospy.internal][INFO] 2018-12-19 11:22:44,917: topic[/run_behavior/result] adding connection to [/nao_behav_ac], count 0
[rospy.internal][ERROR] 2018-12-19 11:23:06,886: Unable to initiate TCP/IP socket to NAOrobUSB001:59409 (http://NAOrobUSB001:42315/): Traceback (most recent call last):
  File "/opt/ros/kinetic/lib/python2.7/dist-packages/rospy/impl/tcpros_base.py", line 557, in connect
    self.read_header()
  File "/opt/ros/kinetic/lib/python2.7/dist-packages/rospy/impl/tcpros_base.py", line 650, in read_header
    self._validate_header(read_ros_handshake_header(sock, self.read_buff, self.protocol.buff_size))
  File "/opt/ros/kinetic/lib/python2.7/dist-packages/rospy/impl/tcpros_base.py", line 593, in _validate_header
    raise TransportInitError("remote error reported: %s"%header['error'])
TransportInitError: remote error reported: received a connection for a nonexistent topic [/run_behavior/cancel] from [TCPROS connection on port 59409 to [127.0.0.1:50904 on socket 10]] [/nao_behaviors].

[rospy.internal][ERROR] 2018-12-19 11:23:06,886: Unable to initiate TCP/IP socket to NAOrobUSB001:59409 (http://NAOrobUSB001:42315/): Traceback (most recent call last):
  File "/opt/ros/kinetic/lib/python2.7/dist-packages/rospy/impl/tcpros_base.py", line 557, in connect
    self.read_header()
  File "/opt/ros/kinetic/lib/python2.7/dist-packages/rospy/impl/tcpros_base.py", line 650, in read_header
    self._validate_header(read_ros_handshake_header(sock, self.read_buff, self.protocol.buff_size))
  File "/opt/ros/kinetic/lib/python2.7/dist-packages/rospy/impl/tcpros_base.py", line 593, in _validate_header
    raise TransportInitError("remote error reported: %s"%header['error'])
TransportInitError: remote error reported: received a connection for a nonexistent topic [/run_behavior/goal] from [TCPROS connection on port 59409 to [127.0.0.1:50908 on socket 10]] [/nao_behaviors].

[rospy.internal][INFO] 2018-12-19 11:23:07,265: topic[/run_behavior/status] removing connection to /nao_behav_ac
[rospy.internal][INFO] 2018-12-19 11:23:07,266: topic[/run_behavior/result] removing connection to /nao_behav_ac
[rospy.internal][INFO] 2018-12-19 11:23:07,266: topic[/run_behavior/feedback] removing connection to /nao_behav_ac
[rospy.internal][WARNING] 2018-12-19 11:23:07,887: Unknown error initiating TCP/IP socket to NAOrobUSB001:59409 (http://NAOrobUSB001:42315/): Traceback (most recent call last):
  File "/opt/ros/kinetic/lib/python2.7/dist-packages/rospy/impl/tcpros_base.py", line 555, in connect
    self.socket.connect((dest_addr, dest_port))
  File "/usr/lib/python2.7/socket.py", line 228, in meth
    return getattr(self._sock,name)(*args)
error: [Errno 111] Connection refused

[rospy.internal][INFO] 2018-12-19 11:23:07,887: topic[/run_behavior/cancel] removing connection to http://NAOrobUSB001:42315/
[rospy.internal][WARNING] 2018-12-19 11:23:07,888: Unknown error initiating TCP/IP socket to NAOrobUSB001:59409 (http://NAOrobUSB001:42315/): Traceback (most recent call last):
  File "/opt/ros/kinetic/lib/python2.7/dist-packages/rospy/impl/tcpros_base.py", line 555, in connect
    self.socket.connect((dest_addr, dest_port))
  File "/usr/lib/python2.7/socket.py", line 228, in meth
    return getattr(self._sock,name)(*args)
error: [Errno 111] Connection refused

[rospy.internal][INFO] 2018-12-19 11:23:07,888: topic[/run_behavior/goal] removing connection to http://NAOrobUSB001:42315/
[rospy.internal][INFO] 2018-12-19 11:23:37,043: topic[/run_behavior/goal] adding connection to [http://NAOrobUSB001:45733/], count 0
[rospy.internal][INFO] 2018-12-19 11:23:37,043: topic[/run_behavior/cancel] adding connection to [http://NAOrobUSB001:45733/], count 0
[rospy.internal][INFO] 2018-12-19 11:23:37,194: topic[/run_behavior/status] adding connection to [/nao_behav_ac], count 0
[rospy.internal][INFO] 2018-12-19 11:23:37,194: topic[/run_behavior/feedback] adding connection to [/nao_behav_ac], count 0
[rospy.internal][INFO] 2018-12-19 11:23:37,194: topic[/run_behavior/result] adding connection to [/nao_behav_ac], count 0
[rospy.internal][ERROR] 2018-12-19 11:23:59,154: Unable to initiate TCP/IP socket to NAOrobUSB001:59899 (http://NAOrobUSB001:45733/): Traceback (most recent call last):
  File "/opt/ros/kinetic/lib/python2.7/dist-packages/rospy/impl/tcpros_base.py", line 557, in connect
    self.read_header()
  File "/opt/ros/kinetic/lib/python2.7/dist-packages/rospy/impl/tcpros_base.py", line 650, in read_header
    self._validate_header(read_ros_handshake_header(sock, self.read_buff, self.protocol.buff_size))
  File "/opt/ros/kinetic/lib/python2.7/dist-packages/rospy/impl/tcpros_base.py", line 593, in _validate_header
    raise TransportInitError("remote error reported: %s"%header['error'])
TransportInitError: remote error reported: received a connection for a nonexistent topic [/run_behavior/cancel] from [TCPROS connection on port 59899 to [127.0.0.1:58214 on socket 10]] [/nao_behaviors].

[rospy.internal][ERROR] 2018-12-19 11:23:59,154: Unable to initiate TCP/IP socket to NAOrobUSB001:59899 (http://NAOrobUSB001:45733/): Traceback (most recent call last):
  File "/opt/ros/kinetic/lib/python2.7/dist-packages/rospy/impl/tcpros_base.py", line 557, in connect
    self.read_header()
  File "/opt/ros/kinetic/lib/python2.7/dist-packages/rospy/impl/tcpros_base.py", line 650, in read_header
    self._validate_header(read_ros_handshake_header(sock, self.read_buff, self.protocol.buff_size))
  File "/opt/ros/kinetic/lib/python2.7/dist-packages/rospy/impl/tcpros_base.py", line 593, in _validate_header
    raise TransportInitError("remote error reported: %s"%header['error'])
TransportInitError: remote error reported: received a connection for a nonexistent topic [/run_behavior/goal] from [TCPROS connection on port 59899 to [127.0.0.1:58218 on socket 10]] [/nao_behaviors].

[rospy.internal][INFO] 2018-12-19 11:23:59,481: topic[/run_behavior/status] removing connection to /nao_behav_ac
[rospy.internal][INFO] 2018-12-19 11:23:59,551: topic[/run_behavior/result] removing connection to /nao_behav_ac
[rospy.internal][INFO] 2018-12-19 11:23:59,552: topic[/run_behavior/feedback] removing connection to /nao_behav_ac
[rospy.internal][WARNING] 2018-12-19 11:24:00,156: Unknown error initiating TCP/IP socket to NAOrobUSB001:59899 (http://NAOrobUSB001:45733/): Traceback (most recent call last):
  File "/opt/ros/kinetic/lib/python2.7/dist-packages/rospy/impl/tcpros_base.py", line 555, in connect
    self.socket.connect((dest_addr, dest_port))
  File "/usr/lib/python2.7/socket.py", line 228, in meth
    return getattr(self._sock,name)(*args)
error: [Errno 111] Connection refused

[rospy.internal][INFO] 2018-12-19 11:24:00,156: topic[/run_behavior/cancel] removing connection to http://NAOrobUSB001:45733/
[rospy.internal][WARNING] 2018-12-19 11:24:00,156: Unknown error initiating TCP/IP socket to NAOrobUSB001:59899 (http://NAOrobUSB001:45733/): Traceback (most recent call last):
  File "/opt/ros/kinetic/lib/python2.7/dist-packages/rospy/impl/tcpros_base.py", line 555, in connect
    self.socket.connect((dest_addr, dest_port))
  File "/usr/lib/python2.7/socket.py", line 228, in meth
    return getattr(self._sock,name)(*args)
error: [Errno 111] Connection refused

[rospy.internal][INFO] 2018-12-19 11:24:00,156: topic[/run_behavior/goal] removing connection to http://NAOrobUSB001:45733/
[rospy.core][INFO] 2018-12-19 11:36:24,001: signal_shutdown [signal-2]
[rosout][INFO] 2018-12-19 11:36:24,002: Stopping nao_behaviors
[rosout][INFO] 2018-12-19 11:36:24,003: nao_behaviors stopped
[rospy.internal][INFO] 2018-12-19 11:36:24,010: topic[/rosout] removing connection to /rosout
[rospy.impl.masterslave][INFO] 2018-12-19 11:36:24,010: signal-2
[rosout][INFO] 2018-12-19 11:36:24,126: nao_behaviors stopped.
[rospy.core][INFO] 2018-12-19 11:36:24,127: signal_shutdown [atexit]
