[rospy.client][INFO] 2018-12-05 11:49:55,453: init_node, name[/naoqi_moveto], pid[14446]
[xmlrpc][INFO] 2018-12-05 11:49:55,453: XML-RPC server binding to 0.0.0.0:0
[xmlrpc][INFO] 2018-12-05 11:49:55,454: Started XML-RPC server [http://NAOrobUSB001:39883/]
[rospy.init][INFO] 2018-12-05 11:49:55,454: ROS Slave URI: [http://NAOrobUSB001:39883/]
[rospy.impl.masterslave][INFO] 2018-12-05 11:49:55,454: _ready: http://NAOrobUSB001:39883/
[rospy.registration][INFO] 2018-12-05 11:49:55,454: Registering with master node http://localhost:11311
[xmlrpc][INFO] 2018-12-05 11:49:55,454: xml rpc node: starting XML-RPC server
[rospy.init][INFO] 2018-12-05 11:49:55,554: registered with master
[rospy.rosout][INFO] 2018-12-05 11:49:55,554: initializing /rosout core topic
[rospy.rosout][INFO] 2018-12-05 11:49:55,558: connected to core topic /rosout
[rospy.simtime][INFO] 2018-12-05 11:49:55,561: /use_sim_time is not set, will not subscribe to simulated time [/clock] topic
[rosout][INFO] 2018-12-05 11:49:55,571: Connecting to NaoQi at 127.0.0.1:9559
[rospy.internal][INFO] 2018-12-05 11:49:55,619: topic[/tf_static] adding connection to [http://NAOrobUSB001:45903/], count 0
[rospy.internal][INFO] 2018-12-05 11:49:55,619: topic[/tf] adding connection to [http://NAOrobUSB001:41623/], count 0
[rospy.internal][INFO] 2018-12-05 11:49:55,620: topic[/tf] adding connection to [http://NAOrobUSB001:45903/], count 0
[rospy.internal][INFO] 2018-12-05 11:49:55,627: topic[/tf] adding connection to [http://NAOrobUSB001:38817/], count 2
[rospy.internal][INFO] 2018-12-05 11:49:55,822: topic[/rosout] adding connection to [/rosout], count 0
[rospy.internal][INFO] 2018-12-05 11:53:01,016: topic[/move_base_simple/goal] adding connection to [http://NAOrobUSB001:34757/], count 0
[rospy.internal][INFO] 2018-12-05 12:01:12,534: topic[/cmd_vel] adding connection to [http://NAOrobUSB001:41913/], count 0
[rospy.internal][ERROR] 2018-12-05 12:01:15,476: Unable to initiate TCP/IP socket to NAOrobUSB001:40439 (http://NAOrobUSB001:41913/): Traceback (most recent call last):
  File "/opt/ros/kinetic/lib/python2.7/dist-packages/rospy/impl/tcpros_base.py", line 557, in connect
    self.read_header()
  File "/opt/ros/kinetic/lib/python2.7/dist-packages/rospy/impl/tcpros_base.py", line 650, in read_header
    self._validate_header(read_ros_handshake_header(sock, self.read_buff, self.protocol.buff_size))
  File "/opt/ros/kinetic/lib/python2.7/dist-packages/rospy/impl/tcpros_base.py", line 593, in _validate_header
    raise TransportInitError("remote error reported: %s"%header['error'])
TransportInitError: remote error reported: node shutting down

[rospy.internal][WARNING] 2018-12-05 12:01:16,476: Unknown error initiating TCP/IP socket to NAOrobUSB001:40439 (http://NAOrobUSB001:41913/): Traceback (most recent call last):
  File "/opt/ros/kinetic/lib/python2.7/dist-packages/rospy/impl/tcpros_base.py", line 555, in connect
    self.socket.connect((dest_addr, dest_port))
  File "/usr/lib/python2.7/socket.py", line 228, in meth
    return getattr(self._sock,name)(*args)
error: [Errno 111] Connection refused

[rospy.internal][INFO] 2018-12-05 12:01:16,477: topic[/cmd_vel] removing connection to http://NAOrobUSB001:41913/
[rospy.internal][INFO] 2018-12-05 12:02:09,516: topic[/cmd_vel] adding connection to [http://NAOrobUSB001:46777/], count 0
[rospy.internal][WARNING] 2018-12-05 12:02:12,458: Unknown error initiating TCP/IP socket to NAOrobUSB001:40387 (http://NAOrobUSB001:46777/): Traceback (most recent call last):
  File "/opt/ros/kinetic/lib/python2.7/dist-packages/rospy/impl/tcpros_base.py", line 557, in connect
    self.read_header()
  File "/opt/ros/kinetic/lib/python2.7/dist-packages/rospy/impl/tcpros_base.py", line 650, in read_header
    self._validate_header(read_ros_handshake_header(sock, self.read_buff, self.protocol.buff_size))
  File "/opt/ros/kinetic/lib/python2.7/dist-packages/rosgraph/network.py", line 362, in read_ros_handshake_header
    d = sock.recv(buff_size)
error: [Errno 104] Connection reset by peer

[rospy.internal][INFO] 2018-12-05 12:02:12,459: topic[/cmd_vel] removing connection to http://NAOrobUSB001:46777/
[rospy.internal][INFO] 2018-12-05 12:03:11,400: topic[/cmd_vel] adding connection to [http://NAOrobUSB001:40423/], count 0
[rospy.internal][WARNING] 2018-12-05 12:03:14,346: Unknown error initiating TCP/IP socket to NAOrobUSB001:39725 (http://NAOrobUSB001:40423/): Traceback (most recent call last):
  File "/opt/ros/kinetic/lib/python2.7/dist-packages/rospy/impl/tcpros_base.py", line 557, in connect
    self.read_header()
  File "/opt/ros/kinetic/lib/python2.7/dist-packages/rospy/impl/tcpros_base.py", line 650, in read_header
    self._validate_header(read_ros_handshake_header(sock, self.read_buff, self.protocol.buff_size))
  File "/opt/ros/kinetic/lib/python2.7/dist-packages/rosgraph/network.py", line 362, in read_ros_handshake_header
    d = sock.recv(buff_size)
error: [Errno 104] Connection reset by peer

[rospy.internal][INFO] 2018-12-05 12:03:14,346: topic[/cmd_vel] removing connection to http://NAOrobUSB001:40423/
[rospy.internal][INFO] 2018-12-05 12:04:52,692: topic[/cmd_vel] adding connection to [http://NAOrobUSB001:46541/], count 0
[rospy.internal][ERROR] 2018-12-05 12:04:55,641: Unable to initiate TCP/IP socket to NAOrobUSB001:33565 (http://NAOrobUSB001:46541/): Traceback (most recent call last):
  File "/opt/ros/kinetic/lib/python2.7/dist-packages/rospy/impl/tcpros_base.py", line 557, in connect
    self.read_header()
  File "/opt/ros/kinetic/lib/python2.7/dist-packages/rospy/impl/tcpros_base.py", line 650, in read_header
    self._validate_header(read_ros_handshake_header(sock, self.read_buff, self.protocol.buff_size))
  File "/opt/ros/kinetic/lib/python2.7/dist-packages/rospy/impl/tcpros_base.py", line 593, in _validate_header
    raise TransportInitError("remote error reported: %s"%header['error'])
TransportInitError: remote error reported: node shutting down

[rospy.internal][WARNING] 2018-12-05 12:04:56,643: Unknown error initiating TCP/IP socket to NAOrobUSB001:33565 (http://NAOrobUSB001:46541/): Traceback (most recent call last):
  File "/opt/ros/kinetic/lib/python2.7/dist-packages/rospy/impl/tcpros_base.py", line 555, in connect
    self.socket.connect((dest_addr, dest_port))
  File "/usr/lib/python2.7/socket.py", line 228, in meth
    return getattr(self._sock,name)(*args)
error: [Errno 111] Connection refused

[rospy.internal][INFO] 2018-12-05 12:04:56,643: topic[/cmd_vel] removing connection to http://NAOrobUSB001:46541/
[rospy.internal][INFO] 2018-12-05 12:05:09,911: topic[/cmd_vel] adding connection to [http://NAOrobUSB001:39055/], count 0
[rospy.internal][ERROR] 2018-12-05 12:05:12,908: Unable to initiate TCP/IP socket to NAOrobUSB001:42045 (http://NAOrobUSB001:39055/): Traceback (most recent call last):
  File "/opt/ros/kinetic/lib/python2.7/dist-packages/rospy/impl/tcpros_base.py", line 557, in connect
    self.read_header()
  File "/opt/ros/kinetic/lib/python2.7/dist-packages/rospy/impl/tcpros_base.py", line 650, in read_header
    self._validate_header(read_ros_handshake_header(sock, self.read_buff, self.protocol.buff_size))
  File "/opt/ros/kinetic/lib/python2.7/dist-packages/rospy/impl/tcpros_base.py", line 593, in _validate_header
    raise TransportInitError("remote error reported: %s"%header['error'])
TransportInitError: remote error reported: node shutting down

[rospy.internal][WARNING] 2018-12-05 12:05:13,910: Unknown error initiating TCP/IP socket to NAOrobUSB001:42045 (http://NAOrobUSB001:39055/): Traceback (most recent call last):
  File "/opt/ros/kinetic/lib/python2.7/dist-packages/rospy/impl/tcpros_base.py", line 555, in connect
    self.socket.connect((dest_addr, dest_port))
  File "/usr/lib/python2.7/socket.py", line 228, in meth
    return getattr(self._sock,name)(*args)
error: [Errno 111] Connection refused

[rospy.internal][INFO] 2018-12-05 12:05:13,910: topic[/cmd_vel] removing connection to http://NAOrobUSB001:39055/
[rospy.internal][INFO] 2018-12-05 12:05:16,527: topic[/cmd_vel] adding connection to [http://NAOrobUSB001:36691/], count 0
[rospy.internal][ERROR] 2018-12-05 12:05:19,477: Unable to initiate TCP/IP socket to NAOrobUSB001:44037 (http://NAOrobUSB001:36691/): Traceback (most recent call last):
  File "/opt/ros/kinetic/lib/python2.7/dist-packages/rospy/impl/tcpros_base.py", line 557, in connect
    self.read_header()
  File "/opt/ros/kinetic/lib/python2.7/dist-packages/rospy/impl/tcpros_base.py", line 650, in read_header
    self._validate_header(read_ros_handshake_header(sock, self.read_buff, self.protocol.buff_size))
  File "/opt/ros/kinetic/lib/python2.7/dist-packages/rospy/impl/tcpros_base.py", line 593, in _validate_header
    raise TransportInitError("remote error reported: %s"%header['error'])
TransportInitError: remote error reported: node shutting down

[rospy.internal][WARNING] 2018-12-05 12:05:20,478: Unknown error initiating TCP/IP socket to NAOrobUSB001:44037 (http://NAOrobUSB001:36691/): Traceback (most recent call last):
  File "/opt/ros/kinetic/lib/python2.7/dist-packages/rospy/impl/tcpros_base.py", line 555, in connect
    self.socket.connect((dest_addr, dest_port))
  File "/usr/lib/python2.7/socket.py", line 228, in meth
    return getattr(self._sock,name)(*args)
error: [Errno 111] Connection refused

[rospy.internal][INFO] 2018-12-05 12:05:20,479: topic[/cmd_vel] removing connection to http://NAOrobUSB001:36691/
[rospy.internal][INFO] 2018-12-05 12:05:23,144: topic[/cmd_vel] adding connection to [http://NAOrobUSB001:35171/], count 0
[rospy.internal][ERROR] 2018-12-05 12:05:26,057: Unable to initiate TCP/IP socket to NAOrobUSB001:42561 (http://NAOrobUSB001:35171/): Traceback (most recent call last):
  File "/opt/ros/kinetic/lib/python2.7/dist-packages/rospy/impl/tcpros_base.py", line 557, in connect
    self.read_header()
  File "/opt/ros/kinetic/lib/python2.7/dist-packages/rospy/impl/tcpros_base.py", line 650, in read_header
    self._validate_header(read_ros_handshake_header(sock, self.read_buff, self.protocol.buff_size))
  File "/opt/ros/kinetic/lib/python2.7/dist-packages/rospy/impl/tcpros_base.py", line 593, in _validate_header
    raise TransportInitError("remote error reported: %s"%header['error'])
TransportInitError: remote error reported: node shutting down

[rospy.internal][WARNING] 2018-12-05 12:05:27,058: Unknown error initiating TCP/IP socket to NAOrobUSB001:42561 (http://NAOrobUSB001:35171/): Traceback (most recent call last):
  File "/opt/ros/kinetic/lib/python2.7/dist-packages/rospy/impl/tcpros_base.py", line 555, in connect
    self.socket.connect((dest_addr, dest_port))
  File "/usr/lib/python2.7/socket.py", line 228, in meth
    return getattr(self._sock,name)(*args)
error: [Errno 111] Connection refused

[rospy.internal][INFO] 2018-12-05 12:05:27,058: topic[/cmd_vel] removing connection to http://NAOrobUSB001:35171/
[rospy.internal][INFO] 2018-12-05 12:05:34,861: topic[/cmd_vel] adding connection to [http://NAOrobUSB001:34781/], count 0
[rospy.internal][ERROR] 2018-12-05 12:05:37,805: Unable to initiate TCP/IP socket to NAOrobUSB001:38897 (http://NAOrobUSB001:34781/): Traceback (most recent call last):
  File "/opt/ros/kinetic/lib/python2.7/dist-packages/rospy/impl/tcpros_base.py", line 557, in connect
    self.read_header()
  File "/opt/ros/kinetic/lib/python2.7/dist-packages/rospy/impl/tcpros_base.py", line 650, in read_header
    self._validate_header(read_ros_handshake_header(sock, self.read_buff, self.protocol.buff_size))
  File "/opt/ros/kinetic/lib/python2.7/dist-packages/rospy/impl/tcpros_base.py", line 593, in _validate_header
    raise TransportInitError("remote error reported: %s"%header['error'])
TransportInitError: remote error reported: node shutting down

[rospy.internal][WARNING] 2018-12-05 12:05:38,806: Unknown error initiating TCP/IP socket to NAOrobUSB001:38897 (http://NAOrobUSB001:34781/): Traceback (most recent call last):
  File "/opt/ros/kinetic/lib/python2.7/dist-packages/rospy/impl/tcpros_base.py", line 555, in connect
    self.socket.connect((dest_addr, dest_port))
  File "/usr/lib/python2.7/socket.py", line 228, in meth
    return getattr(self._sock,name)(*args)
error: [Errno 111] Connection refused

[rospy.internal][INFO] 2018-12-05 12:05:38,806: topic[/cmd_vel] removing connection to http://NAOrobUSB001:34781/
[rospy.internal][INFO] 2018-12-05 12:05:40,977: topic[/cmd_vel] adding connection to [http://NAOrobUSB001:43229/], count 0
[rospy.internal][ERROR] 2018-12-05 12:05:43,896: Unable to initiate TCP/IP socket to NAOrobUSB001:34451 (http://NAOrobUSB001:43229/): Traceback (most recent call last):
  File "/opt/ros/kinetic/lib/python2.7/dist-packages/rospy/impl/tcpros_base.py", line 557, in connect
    self.read_header()
  File "/opt/ros/kinetic/lib/python2.7/dist-packages/rospy/impl/tcpros_base.py", line 650, in read_header
    self._validate_header(read_ros_handshake_header(sock, self.read_buff, self.protocol.buff_size))
  File "/opt/ros/kinetic/lib/python2.7/dist-packages/rospy/impl/tcpros_base.py", line 593, in _validate_header
    raise TransportInitError("remote error reported: %s"%header['error'])
TransportInitError: remote error reported: node shutting down

[rospy.internal][WARNING] 2018-12-05 12:05:44,898: Unknown error initiating TCP/IP socket to NAOrobUSB001:34451 (http://NAOrobUSB001:43229/): Traceback (most recent call last):
  File "/opt/ros/kinetic/lib/python2.7/dist-packages/rospy/impl/tcpros_base.py", line 555, in connect
    self.socket.connect((dest_addr, dest_port))
  File "/usr/lib/python2.7/socket.py", line 228, in meth
    return getattr(self._sock,name)(*args)
error: [Errno 111] Connection refused

[rospy.internal][INFO] 2018-12-05 12:05:44,898: topic[/cmd_vel] removing connection to http://NAOrobUSB001:43229/
[rospy.internal][INFO] 2018-12-05 12:05:53,595: topic[/cmd_vel] adding connection to [http://NAOrobUSB001:41649/], count 0
[rospy.internal][ERROR] 2018-12-05 12:05:56,484: Unable to initiate TCP/IP socket to NAOrobUSB001:37439 (http://NAOrobUSB001:41649/): Traceback (most recent call last):
  File "/opt/ros/kinetic/lib/python2.7/dist-packages/rospy/impl/tcpros_base.py", line 557, in connect
    self.read_header()
  File "/opt/ros/kinetic/lib/python2.7/dist-packages/rospy/impl/tcpros_base.py", line 650, in read_header
    self._validate_header(read_ros_handshake_header(sock, self.read_buff, self.protocol.buff_size))
  File "/opt/ros/kinetic/lib/python2.7/dist-packages/rospy/impl/tcpros_base.py", line 593, in _validate_header
    raise TransportInitError("remote error reported: %s"%header['error'])
TransportInitError: remote error reported: node shutting down

[rospy.internal][WARNING] 2018-12-05 12:05:57,485: Unknown error initiating TCP/IP socket to NAOrobUSB001:37439 (http://NAOrobUSB001:41649/): Traceback (most recent call last):
  File "/opt/ros/kinetic/lib/python2.7/dist-packages/rospy/impl/tcpros_base.py", line 555, in connect
    self.socket.connect((dest_addr, dest_port))
  File "/usr/lib/python2.7/socket.py", line 228, in meth
    return getattr(self._sock,name)(*args)
error: [Errno 111] Connection refused

[rospy.internal][INFO] 2018-12-05 12:05:57,485: topic[/cmd_vel] removing connection to http://NAOrobUSB001:41649/
[rospy.internal][INFO] 2018-12-05 12:23:22,476: topic[/move_base_simple/goal] adding connection to [http://NAOrobUSB001:41379/], count 1
[rospy.internal][ERROR] 2018-12-05 12:23:43,075: Unable to initiate TCP/IP socket to NAOrobUSB001:50173 (http://NAOrobUSB001:34757/): Traceback (most recent call last):
  File "/opt/ros/kinetic/lib/python2.7/dist-packages/rospy/impl/tcpros_base.py", line 557, in connect
    self.read_header()
  File "/opt/ros/kinetic/lib/python2.7/dist-packages/rospy/impl/tcpros_base.py", line 650, in read_header
    self._validate_header(read_ros_handshake_header(sock, self.read_buff, self.protocol.buff_size))
  File "/opt/ros/kinetic/lib/python2.7/dist-packages/rospy/impl/tcpros_base.py", line 593, in _validate_header
    raise TransportInitError("remote error reported: %s"%header['error'])
TransportInitError: remote error reported: received a connection for a nonexistent topic [/move_base_simple/goal] from [TCPROS connection on port 50173 to [127.0.0.1:49776 on socket 29]] [/naoqi_moveto].

[rospy.internal][WARNING] 2018-12-05 12:23:44,077: Unknown error initiating TCP/IP socket to NAOrobUSB001:50173 (http://NAOrobUSB001:34757/): Traceback (most recent call last):
  File "/opt/ros/kinetic/lib/python2.7/dist-packages/rospy/impl/tcpros_base.py", line 555, in connect
    self.socket.connect((dest_addr, dest_port))
  File "/usr/lib/python2.7/socket.py", line 228, in meth
    return getattr(self._sock,name)(*args)
error: [Errno 111] Connection refused

[rospy.internal][INFO] 2018-12-05 12:23:44,077: topic[/move_base_simple/goal] removing connection to http://NAOrobUSB001:34757/
[rospy.internal][ERROR] 2018-12-05 13:45:39,688: Unable to initiate TCP/IP socket to NAOrobUSB001:39739 (http://NAOrobUSB001:38817/): Traceback (most recent call last):
  File "/opt/ros/kinetic/lib/python2.7/dist-packages/rospy/impl/tcpros_base.py", line 557, in connect
    self.read_header()
  File "/opt/ros/kinetic/lib/python2.7/dist-packages/rospy/impl/tcpros_base.py", line 650, in read_header
    self._validate_header(read_ros_handshake_header(sock, self.read_buff, self.protocol.buff_size))
  File "/opt/ros/kinetic/lib/python2.7/dist-packages/rospy/impl/tcpros_base.py", line 593, in _validate_header
    raise TransportInitError("remote error reported: %s"%header['error'])
TransportInitError: remote error reported: node shutting down

[rospy.core][INFO] 2018-12-05 13:45:40,117: signal_shutdown [signal-2]
[rosout][INFO] 2018-12-05 13:45:40,117: Stopping naoqi_moveto_listener
[rosout][INFO] 2018-12-05 13:45:40,118: naoqi_moveto_listener stopped
[rospy.internal][INFO] 2018-12-05 13:45:40,126: topic[/rosout] removing connection to /rosout
[rospy.internal][INFO] 2018-12-05 13:45:40,126: topic[/tf_static] removing connection to http://NAOrobUSB001:45903/
[rospy.internal][INFO] 2018-12-05 13:45:40,126: topic[/move_base_simple/goal] removing connection to http://NAOrobUSB001:41379/
[rospy.internal][INFO] 2018-12-05 13:45:40,126: topic[/tf] removing connection to http://NAOrobUSB001:41623/
[rospy.internal][INFO] 2018-12-05 13:45:40,126: topic[/tf] removing connection to http://NAOrobUSB001:45903/
[rospy.internal][INFO] 2018-12-05 13:45:40,127: topic[/tf] removing connection to http://NAOrobUSB001:38817/
[rospy.impl.masterslave][INFO] 2018-12-05 13:45:40,127: signal-2
[rospy.core][INFO] 2018-12-05 13:45:40,742: signal_shutdown [atexit]
